Certainly! Let's break down exception handling in C++ into simple, beginner-friendly layers.
//LAYER BY LAYER PROMP ROCKS ;0

### Layer 1: Introduction

Exception handling is a mechanism in C++ that helps you deal with errors or unexpected situations in a program. Instead of crashing the program when an error occurs, you can use exception handling to gracefully handle these situations.

### Layer 2: Keywords

1. **`try` block:** This is the block of code where you suspect an exception might occur. It's like saying, "I'm going to try running this code."

    ```cpp
    try {
        // Code that might throw an exception
    }
    ```

2. **`throw` statement:** If an error occurs inside the `try` block, you can use the `throw` keyword to throw an exception.

    ```cpp
    throw "This is an exception!";
    ```

3. **`catch` block:** This block catches and handles the exception thrown in the `try` block.

    ```cpp
    catch (const char* errorMessage) {
        // Code to handle the exception
    }
    ```

### Layer 3: Example

Let's put it together in a simple example:

```cpp
#include <iostream>
using namespace std;

int main() {
    try {
        // Code that might throw an exception
        throw "This is an exception!";
    } catch (const char* errorMessage) {
        // Code to handle the exception
        cout << "Exception caught: " << errorMessage << endl;
    }

    return 0;
}
```

In this example, the `try` block contains code that throws a character array as an exception. The `catch` block catches this exception and prints an error message.

### Layer 4: Handling Different Types of Exceptions

You can catch different types of exceptions using multiple `catch` blocks. For example:

```cpp
try {
    // Code that might throw an exception
    throw runtime_error("This is a runtime error!");
} catch (const char* errorMessage) {
    cout << "Caught a char pointer exception: " << errorMessage << endl;
} catch (const runtime_error& e) {
    cout << "Caught a runtime error: " << e.what() << endl;
}
```

Here, the `try` block throws a `runtime_error`, and the program catches it with the appropriate `catch` block.

### Layer 5: Creating Custom Exceptions

You can create your own custom exception classes by deriving from the standard exception classes. This helps in providing meaningful information about the exception.

```cpp
#include <iostream>
#include <stdexcept>
using namespace std;

class CustomException : public runtime_error {
public:
    CustomException() : runtime_error("This is a custom exception!") {}
};

int main() {
    try {
        throw CustomException();
    } catch (const CustomException& e) {
        cout << "Caught a custom exception: " << e.what() << endl;
    }

    return 0;
}
```

Here, `CustomException` is a custom exception class derived from `runtime_error`. The `what()` function is overridden to provide a description of the exception.

### Summary

- **`try` block:** Contains code that might throw an exception.
- **`throw` statement:** Throws an exception when an error occurs.
- **`catch` block:** Catches and handles exceptions of specific types.
- **Custom Exceptions:** Derive from standard exception classes for meaningful error information.

Remember, exception handling is a powerful tool, but it's essential to use it judiciously and appropriately in your programs.